2024-09-25 00:12:29,066 INFO: KLSNKVs blog startup [in /Users/klsnkv/coding/python/flask_2024/blog_proj/app_package/__init__.py:49]
2024-09-25 00:12:52,824 INFO: KLSNKVs blog startup [in /Users/klsnkv/coding/python/flask_2024/blog_proj/app_package/__init__.py:49]
2024-09-25 00:13:18,199 ERROR: Exception on /edit_profile [POST] [in /Users/klsnkv/coding/python/flask_2024/blog_proj/venv/lib/python3.12/site-packages/flask/app.py:838]
Traceback (most recent call last):
  File "/Users/klsnkv/coding/python/flask_2024/blog_proj/venv/lib/python3.12/site-packages/sqlalchemy/engine/base.py", line 1967, in _exec_single_context
    self.dialect.do_execute(
  File "/Users/klsnkv/coding/python/flask_2024/blog_proj/venv/lib/python3.12/site-packages/sqlalchemy/engine/default.py", line 941, in do_execute
    cursor.execute(statement, parameters)
psycopg2.errors.UniqueViolation: duplicate key value violates unique constraint "ix_user_username"
DETAIL:  Key (username)=(alex) already exists.


The above exception was the direct cause of the following exception:

Traceback (most recent call last):
  File "/Users/klsnkv/coding/python/flask_2024/blog_proj/venv/lib/python3.12/site-packages/flask/app.py", line 1473, in wsgi_app
    response = self.full_dispatch_request()
               ^^^^^^^^^^^^^^^^^^^^^^^^^^^^
  File "/Users/klsnkv/coding/python/flask_2024/blog_proj/venv/lib/python3.12/site-packages/flask/app.py", line 882, in full_dispatch_request
    rv = self.handle_user_exception(e)
         ^^^^^^^^^^^^^^^^^^^^^^^^^^^^^
  File "/Users/klsnkv/coding/python/flask_2024/blog_proj/venv/lib/python3.12/site-packages/flask/app.py", line 880, in full_dispatch_request
    rv = self.dispatch_request()
         ^^^^^^^^^^^^^^^^^^^^^^^
  File "/Users/klsnkv/coding/python/flask_2024/blog_proj/venv/lib/python3.12/site-packages/flask/app.py", line 865, in dispatch_request
    return self.ensure_sync(self.view_functions[rule.endpoint])(**view_args)  # type: ignore[no-any-return]
           ^^^^^^^^^^^^^^^^^^^^^^^^^^^^^^^^^^^^^^^^^^^^^^^^^^^^^^^^^^^^^^^^^
  File "/Users/klsnkv/coding/python/flask_2024/blog_proj/venv/lib/python3.12/site-packages/flask_login/utils.py", line 290, in decorated_view
    return current_app.ensure_sync(func)(*args, **kwargs)
           ^^^^^^^^^^^^^^^^^^^^^^^^^^^^^^^^^^^^^^^^^^^^^^
  File "/Users/klsnkv/coding/python/flask_2024/blog_proj/app_package/routes.py", line 97, in edit_profile
    db.session.commit()
  File "/Users/klsnkv/coding/python/flask_2024/blog_proj/venv/lib/python3.12/site-packages/sqlalchemy/orm/scoping.py", line 597, in commit
    return self._proxied.commit()
           ^^^^^^^^^^^^^^^^^^^^^^
  File "/Users/klsnkv/coding/python/flask_2024/blog_proj/venv/lib/python3.12/site-packages/sqlalchemy/orm/session.py", line 2028, in commit
    trans.commit(_to_root=True)
  File "<string>", line 2, in commit
  File "/Users/klsnkv/coding/python/flask_2024/blog_proj/venv/lib/python3.12/site-packages/sqlalchemy/orm/state_changes.py", line 139, in _go
    ret_value = fn(self, *arg, **kw)
                ^^^^^^^^^^^^^^^^^^^^
  File "/Users/klsnkv/coding/python/flask_2024/blog_proj/venv/lib/python3.12/site-packages/sqlalchemy/orm/session.py", line 1313, in commit
    self._prepare_impl()
  File "<string>", line 2, in _prepare_impl
  File "/Users/klsnkv/coding/python/flask_2024/blog_proj/venv/lib/python3.12/site-packages/sqlalchemy/orm/state_changes.py", line 139, in _go
    ret_value = fn(self, *arg, **kw)
                ^^^^^^^^^^^^^^^^^^^^
  File "/Users/klsnkv/coding/python/flask_2024/blog_proj/venv/lib/python3.12/site-packages/sqlalchemy/orm/session.py", line 1288, in _prepare_impl
    self.session.flush()
  File "/Users/klsnkv/coding/python/flask_2024/blog_proj/venv/lib/python3.12/site-packages/sqlalchemy/orm/session.py", line 4352, in flush
    self._flush(objects)
  File "/Users/klsnkv/coding/python/flask_2024/blog_proj/venv/lib/python3.12/site-packages/sqlalchemy/orm/session.py", line 4487, in _flush
    with util.safe_reraise():
  File "/Users/klsnkv/coding/python/flask_2024/blog_proj/venv/lib/python3.12/site-packages/sqlalchemy/util/langhelpers.py", line 146, in __exit__
    raise exc_value.with_traceback(exc_tb)
  File "/Users/klsnkv/coding/python/flask_2024/blog_proj/venv/lib/python3.12/site-packages/sqlalchemy/orm/session.py", line 4448, in _flush
    flush_context.execute()
  File "/Users/klsnkv/coding/python/flask_2024/blog_proj/venv/lib/python3.12/site-packages/sqlalchemy/orm/unitofwork.py", line 466, in execute
    rec.execute(self)
  File "/Users/klsnkv/coding/python/flask_2024/blog_proj/venv/lib/python3.12/site-packages/sqlalchemy/orm/unitofwork.py", line 642, in execute
    util.preloaded.orm_persistence.save_obj(
  File "/Users/klsnkv/coding/python/flask_2024/blog_proj/venv/lib/python3.12/site-packages/sqlalchemy/orm/persistence.py", line 85, in save_obj
    _emit_update_statements(
  File "/Users/klsnkv/coding/python/flask_2024/blog_proj/venv/lib/python3.12/site-packages/sqlalchemy/orm/persistence.py", line 912, in _emit_update_statements
    c = connection.execute(
        ^^^^^^^^^^^^^^^^^^^
  File "/Users/klsnkv/coding/python/flask_2024/blog_proj/venv/lib/python3.12/site-packages/sqlalchemy/engine/base.py", line 1418, in execute
    return meth(
           ^^^^^
  File "/Users/klsnkv/coding/python/flask_2024/blog_proj/venv/lib/python3.12/site-packages/sqlalchemy/sql/elements.py", line 515, in _execute_on_connection
    return connection._execute_clauseelement(
           ^^^^^^^^^^^^^^^^^^^^^^^^^^^^^^^^^^
  File "/Users/klsnkv/coding/python/flask_2024/blog_proj/venv/lib/python3.12/site-packages/sqlalchemy/engine/base.py", line 1640, in _execute_clauseelement
    ret = self._execute_context(
          ^^^^^^^^^^^^^^^^^^^^^^
  File "/Users/klsnkv/coding/python/flask_2024/blog_proj/venv/lib/python3.12/site-packages/sqlalchemy/engine/base.py", line 1846, in _execute_context
    return self._exec_single_context(
           ^^^^^^^^^^^^^^^^^^^^^^^^^^
  File "/Users/klsnkv/coding/python/flask_2024/blog_proj/venv/lib/python3.12/site-packages/sqlalchemy/engine/base.py", line 1986, in _exec_single_context
    self._handle_dbapi_exception(
  File "/Users/klsnkv/coding/python/flask_2024/blog_proj/venv/lib/python3.12/site-packages/sqlalchemy/engine/base.py", line 2355, in _handle_dbapi_exception
    raise sqlalchemy_exception.with_traceback(exc_info[2]) from e
  File "/Users/klsnkv/coding/python/flask_2024/blog_proj/venv/lib/python3.12/site-packages/sqlalchemy/engine/base.py", line 1967, in _exec_single_context
    self.dialect.do_execute(
  File "/Users/klsnkv/coding/python/flask_2024/blog_proj/venv/lib/python3.12/site-packages/sqlalchemy/engine/default.py", line 941, in do_execute
    cursor.execute(statement, parameters)
sqlalchemy.exc.IntegrityError: (psycopg2.errors.UniqueViolation) duplicate key value violates unique constraint "ix_user_username"
DETAIL:  Key (username)=(alex) already exists.

[SQL: UPDATE "user" SET username=%(username)s, about_me=%(about_me)s WHERE "user".id = %(user_id)s]
[parameters: {'username': 'alex', 'about_me': 'csdcdscds fdsfds  dfdf', 'user_id': 3}]
(Background on this error at: https://sqlalche.me/e/20/gkpj)
2024-09-25 00:21:41,678 INFO: KLSNKVs blog startup [in /Users/klsnkv/coding/python/flask_2024/blog_proj/app_package/__init__.py:49]
2024-09-25 11:53:12,610 INFO: KLSNKVs blog startup [in /Users/klsnkv/coding/python/flask_2024/blog_proj/app_package/__init__.py:49]
2024-09-25 11:53:23,542 INFO: KLSNKVs blog startup [in /Users/klsnkv/coding/python/flask_2024/blog_proj/app_package/__init__.py:49]
2024-09-25 11:53:38,635 INFO: KLSNKVs blog startup [in /Users/klsnkv/coding/python/flask_2024/blog_proj/app_package/__init__.py:49]
2024-09-25 13:45:28,174 INFO: KLSNKVs blog startup [in /Users/klsnkv/coding/python/flask_2024/blog_proj/app_package/__init__.py:49]
2024-09-25 13:46:15,524 INFO: KLSNKVs blog startup [in /Users/klsnkv/coding/python/flask_2024/blog_proj/app_package/__init__.py:49]
2024-09-25 13:56:17,111 INFO: KLSNKVs blog startup [in /Users/klsnkv/coding/python/flask_2024/blog_proj/app_package/__init__.py:49]
2024-09-25 14:31:33,384 INFO: KLSNKVs blog startup [in /Users/klsnkv/coding/python/flask_2024/blog_proj/app_package/__init__.py:49]
2024-09-25 14:53:06,709 INFO: KLSNKVs blog startup [in /Users/klsnkv/coding/python/flask_2024/blog_proj/app_package/__init__.py:49]
2024-09-25 14:53:27,440 ERROR: Exception on /follow/alex [POST] [in /Users/klsnkv/coding/python/flask_2024/blog_proj/venv/lib/python3.12/site-packages/flask/app.py:838]
Traceback (most recent call last):
  File "/Users/klsnkv/coding/python/flask_2024/blog_proj/venv/lib/python3.12/site-packages/flask/app.py", line 1473, in wsgi_app
    response = self.full_dispatch_request()
               ^^^^^^^^^^^^^^^^^^^^^^^^^^^^
  File "/Users/klsnkv/coding/python/flask_2024/blog_proj/venv/lib/python3.12/site-packages/flask/app.py", line 882, in full_dispatch_request
    rv = self.handle_user_exception(e)
         ^^^^^^^^^^^^^^^^^^^^^^^^^^^^^
  File "/Users/klsnkv/coding/python/flask_2024/blog_proj/venv/lib/python3.12/site-packages/flask/app.py", line 880, in full_dispatch_request
    rv = self.dispatch_request()
         ^^^^^^^^^^^^^^^^^^^^^^^
  File "/Users/klsnkv/coding/python/flask_2024/blog_proj/venv/lib/python3.12/site-packages/flask/app.py", line 865, in dispatch_request
    return self.ensure_sync(self.view_functions[rule.endpoint])(**view_args)  # type: ignore[no-any-return]
           ^^^^^^^^^^^^^^^^^^^^^^^^^^^^^^^^^^^^^^^^^^^^^^^^^^^^^^^^^^^^^^^^^
  File "/Users/klsnkv/coding/python/flask_2024/blog_proj/venv/lib/python3.12/site-packages/flask_login/utils.py", line 290, in decorated_view
    return current_app.ensure_sync(func)(*args, **kwargs)
           ^^^^^^^^^^^^^^^^^^^^^^^^^^^^^^^^^^^^^^^^^^^^^^
  File "/Users/klsnkv/coding/python/flask_2024/blog_proj/app_package/routes.py", line 112, in follow
    if form.validate_on_submin():
       ^^^^^^^^^^^^^^^^^^^^^^^
AttributeError: 'EmptyForm' object has no attribute 'validate_on_submin'. Did you mean: 'validate_on_submit'?
